Workbook

Sheet V5 to V6 mapping
A1: Category | B1: V5 variable | C1: V6 variable | D1: Note
A2: 01 — Brand & neutral colors | B2: $color-a | C2: --color-brand-a
A3: 01 — Brand & neutral colors | B3: $color-b | C3: --color-brand-b
A4: 01 — Brand & neutral colors | B4: $color-c | C4: --color-brand-c
A5: 01 — Brand & neutral colors | B5: $color-d | C5: --color-brand-d
A6: 01 — Brand & neutral colors | B6: $color-e | C6: --color-brand-e
A7: 01 — Brand & neutral colors | B7: $color-f | C7: --color-brand-f
A8: 01 — Brand & neutral colors | B8: $color-g | C8: --color-brand-g
A9: 01 — Brand & neutral colors | B9: $color-gray-a | C9: --color-neutral-a
A10: 01 — Brand & neutral colors | B10: $color-gray-b | C10: --color-neutral-b
A11: 01 — Brand & neutral colors | B11: $color-gray-c | C11: --color-neutral-c
A12: 01 — Brand & neutral colors | B12: $color-gray-d | C12: --color-neutral-d
A13: 01 — Brand & neutral colors | B13: $color-gray-e | C13: --color-neutral-e
... A41: 03 — Dark surface colors | B41: $pre-heading-color-bgdark | C41: --pre-heading-color-bg-dark
A42: 04 — Typography family/weight/style | B42: $arrow-appearance | C42: --link-style | D42: If arrow appearance is "right" the make it "left
A43: 04 — Typography family/weight/style | B43: $button-font-family | C43: --button-universal-font-family
A44: 04 — Typography family/weight/style | B44: $button-font-weight | C44: --button-universal-font-weight
A45: 04 — Typography family/weight/style | B45: $button-text-transform | C45: --button-universal-text-transform
A46: 04 — Typography family/weight/style | B46: $footer-heading-font-family | C46: --footer-heading-font-family
A47: 04 — Typography family/weight/style | B47: $footer-heading-font-weight | C47: --footer-heading-font-weight
A48: 04 — Typography family/weight/style | B48: $footer-heading-text-transform | C48: --footer-heading-text-transform
A49: 04 — Typography family/weight/style | B49: $h1-font-family | C49: --h1-font-family
A50: 04 — Typography family/weight/style | B50: $h1-font-weight | C50: --h1-font-weight
A51: 04 — Typography family/weight/style | B51: $h1-text-transform | C51: --h1-text-transform
A52: 04 — Typography family/weight/style | B52: $h2-font-family | C52: --h2-font-family
A53: 04 — Typography family/weight/style | B53: $h2-font-weight | C53: --h2-font-weight
A54: 04 — Typography family/weight/style | B54: $h2-text-transform | C54: --h2-text-transform
... A79: 04 — Typography family/weight/style | B79: $nav-burger-service-links-font-weight | C79: --nav-burger-dropdown-service-link-font-weight
A80: 04 — Typography family/weight/style | B80: $nav-main-font-headings | C80: --nav-main-font-family | D80: if 'true' use --font-heading-family
A81: 04 — Typography family/weight/style | B81: $nav-main-link-font-weight | C81: --nav-main-link-font-weight
A82: 04 — Typography family/weight/style | B82: $nav-main-link-text-transform | C82: --nav-main-link-text-transform
A83: 04 — Typography family/weight/style | B83: $pre-heading-text-transform | C83: --pre-heading-text-transform
A84: 04 — Typography family/weight/style | B84: $service-font-family | C84: --service-font-family
A85: 04 — Typography family/weight/style | B85: $service-font-weight | C85: --service-font-weight
A86: 04 — Typography family/weight/style | B86: $service-text-transform | C86: --service-text-transform
A87: 05 — Font sizes & line-heights | B87: $button-font-size | C87: --button-universal-font-size
A88: 05 — Font sizes & line-heights | B88: $font-large | C88: --font-large
A89: 05 — Font sizes & line-heights | B89: $font-large-line-height | C89: --font-large-line-height
A90: 05 — Font sizes & line-heights | B90: $font-medium | C90: --font-medium
A91: 05 — Font sizes & line-heights | B91: $font-medium | C91: --font-xlarge-size-span-1-9
...

Sheet Summary
A1: V5 → V6 mapping summary
A3: Category | B3: Mappings
A4: 01 — Brand & neutral colors | B4: =COUNTIF('V5 to V6 mapping'!A:A,A4)
A5: 02 — Typography colors | B5: =COUNTIF('V5 to V6 mapping'!A:A,A5)
A6: 03 — Dark surface colors | B6: =COUNTIF('V5 to V6 mapping'!A:A,A6)
A7: 04 — Typography family/weight/style | B7: =COUNTIF('V5 to V6 mapping'!A:A,A7)
A8: 05 — Font sizes & line-heights | B8: =COUNTIF('V5 to V6 mapping'!A:A,A8)
A9: 06 — Layout & containers | B9: =COUNTIF('V5 to V6 mapping'!A:A,A9)
A10: 07 — Borders, radius & shadow | B10: =COUNTIF('V5 to V6 mapping'!A:A,A10)
A11: 08 — Header | B11: =COUNTIF('V5 to V6 mapping'!A:A,A11)
A12: 09 — Footer | B12: =COUNTIF('V5 to V6 mapping'!A:A,A12)
A13: 10 — Main navigation | B13: =COUNTIF('V5 to V6 mapping'!A:A,A13)
A14: 11 — Burger menu | B14: =COUNTIF('V5 to V6 mapping'!A:A,A14)
A15: 12 — Mega menu | B15: =COUNTIF('V5 to V6 mapping'!A:A,A15)
... A24: 99 — Other | B24: =COUNTIF('V5 to V6 mapping'!A:A,A24)
A25: Total | B25: =SUM(B4:B24)

Sheet Conversion rules
A1: Topic | B1: Behaviour
A2: Direct rename | B2: Most V5 variables map 1-to-1 to a V6 variable. The CSV mapping is the lookup.
A3: One V5 → many V6 | B3: $color-a feeds 5 V6 vars (--color-brand-a, --universal-accent-color, dark-surface variants). $color-white feeds 12.
A4: notset sentinel | B4: If V5 theme says '$foo: notset' but the V5 framework default has a real value, the V6 var inherits that base default (e.g. nav-main-border-top → '0 solid var(--color-neutral-d)').
A5: Single-axis reduction | B5: Multi-axis V5 shorthands like '32px 0' are reduced to their first token when the V6 var is consumed single-axis (currently --header-container-padding).
A6: Aspect-ratio normalization | B6: For V6 vars matching '-ratio': '16 9' → '16/9', '2 / 1' → '2/1', 'calc(16 / 9)' → '16/9'.
A7: Hex extraction | B7: CSV note 'take only hex value' strips input to '#rrggbb'.
A8: Arrow appearance | B8: Values left/right/underline on --link-style normalize to 'Left' / 'Underline'.
A9: Boolean-conditional | B9: CSV note 'if true use --foo' substitutes a var() reference when V5 value is 'true'; 'false' → 'inherit'.
A10: Color de-duplication | B10: Hex values matching a --color-brand-* are replaced with the matching var() reference.
A11: Color keywords | B11: 'white' → var(--color-neutral-f). Font-size keywords (small, medium, large …) → var(--font-*).
A12: SCSS arithmetic | B12: Inline math like '24px - 4px' wrapped in calc() so V6 CSS accepts it.
A13: Span variables | B13: Any V6 var name containing 'span' is skipped (deprecated/internal).
